Traceback (most recent call last):
  File "/home/mmann1123/miniconda3/envs/pygis/lib/python3.11/site-packages/jupyter_cache/executors/utils.py", line 58, in single_nb_execution
    executenb(
  File "/home/mmann1123/miniconda3/envs/pygis/lib/python3.11/site-packages/nbclient/client.py", line 1314, in execute
    return NotebookClient(nb=nb, resources=resources, km=km, **kwargs).execute()
           ^^^^^^^^^^^^^^^^^^^^^^^^^^^^^^^^^^^^^^^^^^^^^^^^^^^^^^^^^^^^^^^^^^^^^
  File "/home/mmann1123/miniconda3/envs/pygis/lib/python3.11/site-packages/jupyter_core/utils/__init__.py", line 165, in wrapped
    return loop.run_until_complete(inner)
           ^^^^^^^^^^^^^^^^^^^^^^^^^^^^^^
  File "/home/mmann1123/miniconda3/envs/pygis/lib/python3.11/asyncio/base_events.py", line 653, in run_until_complete
    return future.result()
           ^^^^^^^^^^^^^^^
  File "/home/mmann1123/miniconda3/envs/pygis/lib/python3.11/site-packages/nbclient/client.py", line 709, in async_execute
    await self.async_execute_cell(
  File "/home/mmann1123/miniconda3/envs/pygis/lib/python3.11/site-packages/nbclient/client.py", line 1062, in async_execute_cell
    await self._check_raise_for_error(cell, cell_index, exec_reply)
  File "/home/mmann1123/miniconda3/envs/pygis/lib/python3.11/site-packages/nbclient/client.py", line 918, in _check_raise_for_error
    raise CellExecutionError.from_cell_and_msg(cell, exec_reply_content)
nbclient.exceptions.CellExecutionError: An error occurred while executing the following cell:
------------------
import geopandas
import contextily as ctx
# Download Natural Earth Populated Places
cities = geopandas.read_file('https://d2ad6b4ur7yvpq.cloudfront.net/naturalearth-3.3.0/ne_50m_populated_places.geojson')
cities = cities[cities.name == 'Washington, D.C.']
cities = cities.to_crs(epsg=3857) # project to webmercator

ax = cities.plot(figsize=(10, 10), alpha=0.5, edgecolor='k')
ctx.add_basemap(ax, source=ctx.providers.CartoDB.Positron,zoom = 6, reset_extent = True)
------------------


[0;31m---------------------------------------------------------------------------[0m
[0;31mAttributeError[0m                            Traceback (most recent call last)
[0;32m/tmp/ipykernel_1189545/887999542.py[0m in [0;36m?[0;34m()[0m
[1;32m      1[0m [0;32mimport[0m [0mgeopandas[0m[0;34m[0m[0;34m[0m[0m
[1;32m      2[0m [0;32mimport[0m [0mcontextily[0m [0;32mas[0m [0mctx[0m[0;34m[0m[0;34m[0m[0m
[1;32m      3[0m [0;31m# Download Natural Earth Populated Places[0m[0;34m[0m[0;34m[0m[0m
[1;32m      4[0m [0mcities[0m [0;34m=[0m [0mgeopandas[0m[0;34m.[0m[0mread_file[0m[0;34m([0m[0;34m'https://d2ad6b4ur7yvpq.cloudfront.net/naturalearth-3.3.0/ne_50m_populated_places.geojson'[0m[0;34m)[0m[0;34m[0m[0;34m[0m[0m
[0;32m----> 5[0;31m [0mcities[0m [0;34m=[0m [0mcities[0m[0;34m[[0m[0mcities[0m[0;34m.[0m[0mname[0m [0;34m==[0m [0;34m'Washington, D.C.'[0m[0;34m][0m[0;34m[0m[0;34m[0m[0m
[0m[1;32m      6[0m [0mcities[0m [0;34m=[0m [0mcities[0m[0;34m.[0m[0mto_crs[0m[0;34m([0m[0mepsg[0m[0;34m=[0m[0;36m3857[0m[0;34m)[0m [0;31m# project to webmercator[0m[0;34m[0m[0;34m[0m[0m
[1;32m      7[0m [0;34m[0m[0m
[1;32m      8[0m [0max[0m [0;34m=[0m [0mcities[0m[0;34m.[0m[0mplot[0m[0;34m([0m[0mfigsize[0m[0;34m=[0m[0;34m([0m[0;36m10[0m[0;34m,[0m [0;36m10[0m[0;34m)[0m[0;34m,[0m [0malpha[0m[0;34m=[0m[0;36m0.5[0m[0;34m,[0m [0medgecolor[0m[0;34m=[0m[0;34m'k'[0m[0;34m)[0m[0;34m[0m[0;34m[0m[0m

[0;32m~/miniconda3/envs/pygis/lib/python3.11/site-packages/pandas/core/generic.py[0m in [0;36m?[0;34m(self, name)[0m
[1;32m   6295[0m             [0;32mand[0m [0mname[0m [0;32mnot[0m [0;32min[0m [0mself[0m[0;34m.[0m[0m_accessors[0m[0;34m[0m[0;34m[0m[0m
[1;32m   6296[0m             [0;32mand[0m [0mself[0m[0;34m.[0m[0m_info_axis[0m[0;34m.[0m[0m_can_hold_identifiers_and_holds_name[0m[0;34m([0m[0mname[0m[0;34m)[0m[0;34m[0m[0;34m[0m[0m
[1;32m   6297[0m         ):
[1;32m   6298[0m             [0;32mreturn[0m [0mself[0m[0;34m[[0m[0mname[0m[0;34m][0m[0;34m[0m[0;34m[0m[0m
[0;32m-> 6299[0;31m         [0;32mreturn[0m [0mobject[0m[0;34m.[0m[0m__getattribute__[0m[0;34m([0m[0mself[0m[0;34m,[0m [0mname[0m[0;34m)[0m[0;34m[0m[0;34m[0m[0m
[0m
[0;31mAttributeError[0m: 'GeoDataFrame' object has no attribute 'name'

