Traceback (most recent call last):
  File "/home/mmann1123/miniconda3/envs/pygis/lib/python3.11/site-packages/jupyter_cache/executors/utils.py", line 58, in single_nb_execution
    executenb(
  File "/home/mmann1123/miniconda3/envs/pygis/lib/python3.11/site-packages/nbclient/client.py", line 1314, in execute
    return NotebookClient(nb=nb, resources=resources, km=km, **kwargs).execute()
           ^^^^^^^^^^^^^^^^^^^^^^^^^^^^^^^^^^^^^^^^^^^^^^^^^^^^^^^^^^^^^^^^^^^^^
  File "/home/mmann1123/miniconda3/envs/pygis/lib/python3.11/site-packages/jupyter_core/utils/__init__.py", line 165, in wrapped
    return loop.run_until_complete(inner)
           ^^^^^^^^^^^^^^^^^^^^^^^^^^^^^^
  File "/home/mmann1123/miniconda3/envs/pygis/lib/python3.11/asyncio/base_events.py", line 653, in run_until_complete
    return future.result()
           ^^^^^^^^^^^^^^^
  File "/home/mmann1123/miniconda3/envs/pygis/lib/python3.11/site-packages/nbclient/client.py", line 709, in async_execute
    await self.async_execute_cell(
  File "/home/mmann1123/miniconda3/envs/pygis/lib/python3.11/site-packages/nbclient/client.py", line 1062, in async_execute_cell
    await self._check_raise_for_error(cell, cell_index, exec_reply)
  File "/home/mmann1123/miniconda3/envs/pygis/lib/python3.11/site-packages/nbclient/client.py", line 918, in _check_raise_for_error
    raise CellExecutionError.from_cell_and_msg(cell, exec_reply_content)
nbclient.exceptions.CellExecutionError: An error occurred while executing the following cell:
------------------
# If rainfall point within the polygon, assign that rainfall value to the polygon
tp_polys_clipped_values = gpd.sjoin(rain_train_gdf, tp_polys_clipped, how = "right", op = 'within')

# Drop un-needed column
tp_polys_clipped_values = tp_polys_clipped_values.drop("index_left", axis = 1)

# Rename column
tp_polys_clipped_values = tp_polys_clipped_values.rename(columns = {"Actual_Value": "VALUE_Thiessen"})

# Display head of attribute table
print("Attribute Table: Thiessen Polygon Interpolated Values")
display(tp_polys_clipped_values.head())
------------------


[0;31m---------------------------------------------------------------------------[0m
[0;31mTypeError[0m                                 Traceback (most recent call last)
Cell [0;32mIn[8], line 2[0m
[1;32m      1[0m [38;5;66;03m# If rainfall point within the polygon, assign that rainfall value to the polygon[39;00m
[0;32m----> 2[0m tp_polys_clipped_values [38;5;241m=[39m [43mgpd[49m[38;5;241;43m.[39;49m[43msjoin[49m[43m([49m[43mrain_train_gdf[49m[43m,[49m[43m [49m[43mtp_polys_clipped[49m[43m,[49m[43m [49m[43mhow[49m[43m [49m[38;5;241;43m=[39;49m[43m [49m[38;5;124;43m"[39;49m[38;5;124;43mright[39;49m[38;5;124;43m"[39;49m[43m,[49m[43m [49m[43mop[49m[43m [49m[38;5;241;43m=[39;49m[43m [49m[38;5;124;43m'[39;49m[38;5;124;43mwithin[39;49m[38;5;124;43m'[39;49m[43m)[49m
[1;32m      4[0m [38;5;66;03m# Drop un-needed column[39;00m
[1;32m      5[0m tp_polys_clipped_values [38;5;241m=[39m tp_polys_clipped_values[38;5;241m.[39mdrop([38;5;124m"[39m[38;5;124mindex_left[39m[38;5;124m"[39m, axis [38;5;241m=[39m [38;5;241m1[39m)

File [0;32m~/miniconda3/envs/pygis/lib/python3.11/site-packages/geopandas/tools/sjoin.py:110[0m, in [0;36msjoin[0;34m(left_df, right_df, how, predicate, lsuffix, rsuffix, distance, on_attribute, **kwargs)[0m
[1;32m    108[0m [38;5;28;01mif[39;00m kwargs:
[1;32m    109[0m     first [38;5;241m=[39m [38;5;28mnext[39m([38;5;28miter[39m(kwargs[38;5;241m.[39mkeys()))
[0;32m--> 110[0m     [38;5;28;01mraise[39;00m [38;5;167;01mTypeError[39;00m([38;5;124mf[39m[38;5;124m"[39m[38;5;124msjoin() got an unexpected keyword argument [39m[38;5;124m'[39m[38;5;132;01m{[39;00mfirst[38;5;132;01m}[39;00m[38;5;124m'[39m[38;5;124m"[39m)
[1;32m    112[0m on_attribute [38;5;241m=[39m _maybe_make_list(on_attribute)
[1;32m    114[0m _basic_checks(left_df, right_df, how, lsuffix, rsuffix, on_attribute[38;5;241m=[39mon_attribute),

[0;31mTypeError[0m: sjoin() got an unexpected keyword argument 'op'

