Traceback (most recent call last):
  File "/home/mmann1123/miniconda3/envs/pygis/lib/python3.11/site-packages/jupyter_cache/executors/utils.py", line 58, in single_nb_execution
    executenb(
  File "/home/mmann1123/miniconda3/envs/pygis/lib/python3.11/site-packages/nbclient/client.py", line 1314, in execute
    return NotebookClient(nb=nb, resources=resources, km=km, **kwargs).execute()
           ^^^^^^^^^^^^^^^^^^^^^^^^^^^^^^^^^^^^^^^^^^^^^^^^^^^^^^^^^^^^^^^^^^^^^
  File "/home/mmann1123/miniconda3/envs/pygis/lib/python3.11/site-packages/jupyter_core/utils/__init__.py", line 165, in wrapped
    return loop.run_until_complete(inner)
           ^^^^^^^^^^^^^^^^^^^^^^^^^^^^^^
  File "/home/mmann1123/miniconda3/envs/pygis/lib/python3.11/asyncio/base_events.py", line 653, in run_until_complete
    return future.result()
           ^^^^^^^^^^^^^^^
  File "/home/mmann1123/miniconda3/envs/pygis/lib/python3.11/site-packages/nbclient/client.py", line 709, in async_execute
    await self.async_execute_cell(
  File "/home/mmann1123/miniconda3/envs/pygis/lib/python3.11/site-packages/nbclient/client.py", line 1062, in async_execute_cell
    await self._check_raise_for_error(cell, cell_index, exec_reply)
  File "/home/mmann1123/miniconda3/envs/pygis/lib/python3.11/site-packages/nbclient/client.py", line 918, in _check_raise_for_error
    raise CellExecutionError.from_cell_and_msg(cell, exec_reply_content)
nbclient.exceptions.CellExecutionError: An error occurred while executing the following cell:
------------------
fig, ax = plt.subplots(dpi=200,figsize=(5,5))

with gw.config.update(ref_res=150):
   with gw.open([l8_224078_20200518, l8_224078_20200518], 
                time_names=['t1', 't2'], 
                stack_dim='time', 
                nodata=0) as src:
        y = fit_predict(src, pl, labels, col='lc')
        print(y)
        # plot one time period prediction
        y.sel(time='t1').plot(robust=True, ax=ax)
------------------


[0;31m---------------------------------------------------------------------------[0m
[0;31mValueError[0m                                Traceback (most recent call last)
Cell [0;32mIn[5], line 8[0m
[1;32m      3[0m [38;5;28;01mwith[39;00m gw[38;5;241m.[39mconfig[38;5;241m.[39mupdate(ref_res[38;5;241m=[39m[38;5;241m150[39m):
[1;32m      4[0m    [38;5;28;01mwith[39;00m gw[38;5;241m.[39mopen([l8_224078_20200518, l8_224078_20200518], 
[1;32m      5[0m                 time_names[38;5;241m=[39m[[38;5;124m'[39m[38;5;124mt1[39m[38;5;124m'[39m, [38;5;124m'[39m[38;5;124mt2[39m[38;5;124m'[39m], 
[1;32m      6[0m                 stack_dim[38;5;241m=[39m[38;5;124m'[39m[38;5;124mtime[39m[38;5;124m'[39m, 
[1;32m      7[0m                 nodata[38;5;241m=[39m[38;5;241m0[39m) [38;5;28;01mas[39;00m src:
[0;32m----> 8[0m         y [38;5;241m=[39m [43mfit_predict[49m[43m([49m[43msrc[49m[43m,[49m[43m [49m[43mpl[49m[43m,[49m[43m [49m[43mlabels[49m[43m,[49m[43m [49m[43mcol[49m[38;5;241;43m=[39;49m[38;5;124;43m'[39;49m[38;5;124;43mlc[39;49m[38;5;124;43m'[39;49m[43m)[49m
[1;32m      9[0m         [38;5;28mprint[39m(y)
[1;32m     10[0m         [38;5;66;03m# plot one time period prediction[39;00m

File [0;32m~/miniconda3/envs/pygis/lib/python3.11/site-packages/geowombat/ml/classifiers.py:448[0m, in [0;36mClassifiers.fit_predict[0;34m(self, data, clf, labels, col, targ_name, targ_dim_name, mask_nodataval)[0m
[1;32m    382[0m [38;5;28;01mdef[39;00m [38;5;21mfit_predict[39m(
[1;32m    383[0m     [38;5;28mself[39m,
[1;32m    384[0m     data,
[0;32m   (...)[0m
[1;32m    390[0m     mask_nodataval[38;5;241m=[39m[38;5;28;01mTrue[39;00m,
[1;32m    391[0m ):
[1;32m    392[0m [38;5;250m    [39m[38;5;124;03m"""Fits a classifier given class labels and predicts on a DataArray.[39;00m
[1;32m    393[0m 
[1;32m    394[0m [38;5;124;03m    Args:[39;00m
[0;32m   (...)[0m
[1;32m    445[0m [38;5;124;03m        >>>     y2 = fit_predict(src, cl)[39;00m
[1;32m    446[0m [38;5;124;03m    """[39;00m
[0;32m--> 448[0m     X, Xy, clf [38;5;241m=[39m [38;5;28;43mself[39;49m[38;5;241;43m.[39;49m[43mfit[49m[43m([49m
[1;32m    449[0m [43m        [49m[43mdata[49m[43m,[49m
[1;32m    450[0m [43m        [49m[43mclf[49m[43m,[49m
[1;32m    451[0m [43m        [49m[43mlabels[49m[38;5;241;43m=[39;49m[43mlabels[49m[43m,[49m
[1;32m    452[0m [43m        [49m[43mcol[49m[38;5;241;43m=[39;49m[43mcol[49m[43m,[49m
[1;32m    453[0m [43m        [49m[43mtarg_name[49m[38;5;241;43m=[39;49m[43mtarg_name[49m[43m,[49m
[1;32m    454[0m [43m        [49m[43mtarg_dim_name[49m[38;5;241;43m=[39;49m[43mtarg_dim_name[49m[43m,[49m
[1;32m    455[0m [43m    [49m[43m)[49m
[1;32m    457[0m     y [38;5;241m=[39m [38;5;28mself[39m[38;5;241m.[39mpredict(
[1;32m    458[0m         data, X, clf, targ_name, targ_dim_name, mask_nodataval
[1;32m    459[0m     )
[1;32m    461[0m     [38;5;28;01mreturn[39;00m y

File [0;32m~/miniconda3/envs/pygis/lib/python3.11/site-packages/geowombat/ml/classifiers.py:258[0m, in [0;36mClassifiers.fit[0;34m(self, data, clf, labels, col, targ_name, targ_dim_name)[0m
[1;32m    208[0m [38;5;250m[39m[38;5;124;03m"""Fits a classifier given class labels.[39;00m
[1;32m    209[0m 
[1;32m    210[0m [38;5;124;03mArgs:[39;00m
[0;32m   (...)[0m
[1;32m    254[0m [38;5;124;03m    >>>    X, Xy, clf = fit(src, cl)[39;00m
[1;32m    255[0m [38;5;124;03m"""[39;00m
[1;32m    256[0m [38;5;28;01mif[39;00m data[38;5;241m.[39mgw[38;5;241m.[39mhas_time_coord:
[1;32m    257[0m     [38;5;66;03m# throw error[39;00m
[0;32m--> 258[0m     [38;5;28;01mraise[39;00m [38;5;167;01mValueError[39;00m(
[1;32m    259[0m         [38;5;124m"[39m[38;5;124mDataArray must not have a time coordinate. Use stack_dim=[39m[38;5;124m'[39m[38;5;124mband[39m[38;5;124m'[39m[38;5;124m with gw.open() or use .isel(time=0) to select a single time slice.[39m[38;5;124m"[39m
[1;32m    260[0m     )
[1;32m    261[0m [38;5;28;01mif[39;00m clf[38;5;241m.[39m_estimator_type [38;5;241m==[39m [38;5;124m"[39m[38;5;124mclusterer[39m[38;5;124m"[39m:
[1;32m    262[0m     data [38;5;241m=[39m [38;5;28mself[39m[38;5;241m.[39m_add_time_dim(data)

[0;31mValueError[0m: DataArray must not have a time coordinate. Use stack_dim='band' with gw.open() or use .isel(time=0) to select a single time slice.

