Traceback (most recent call last):
  File "/home/mmann1123/miniconda3/envs/pygis2/lib/python3.10/site-packages/jupyter_cache/executors/utils.py", line 51, in single_nb_execution
    executenb(
  File "/home/mmann1123/miniconda3/envs/pygis2/lib/python3.10/site-packages/nbclient/client.py", line 1204, in execute
    return NotebookClient(nb=nb, resources=resources, km=km, **kwargs).execute()
  File "/home/mmann1123/miniconda3/envs/pygis2/lib/python3.10/site-packages/nbclient/util.py", line 84, in wrapped
    return just_run(coro(*args, **kwargs))
  File "/home/mmann1123/miniconda3/envs/pygis2/lib/python3.10/site-packages/nbclient/util.py", line 62, in just_run
    return loop.run_until_complete(coro)
  File "/home/mmann1123/miniconda3/envs/pygis2/lib/python3.10/asyncio/base_events.py", line 649, in run_until_complete
    return future.result()
  File "/home/mmann1123/miniconda3/envs/pygis2/lib/python3.10/site-packages/nbclient/client.py", line 663, in async_execute
    await self.async_execute_cell(
  File "/home/mmann1123/miniconda3/envs/pygis2/lib/python3.10/site-packages/nbclient/client.py", line 965, in async_execute_cell
    await self._check_raise_for_error(cell, cell_index, exec_reply)
  File "/home/mmann1123/miniconda3/envs/pygis2/lib/python3.10/site-packages/nbclient/client.py", line 862, in _check_raise_for_error
    raise CellExecutionError.from_cell_and_msg(cell, exec_reply_content)
nbclient.exceptions.CellExecutionError: An error occurred while executing the following cell:
------------------
import rasterio
from rasterio.enums import Resampling

image = "../data/LC08_L1TP_224078_20200518_20200518_01_RT.TIF"

upscale_factor = 2

with rasterio.open(image) as dataset:

    # resample data to target shape using upscale_factor
    data = dataset.read(
        out_shape=(
            dataset.count,
            int(dataset.height * upscale_factor),
            int(dataset.width * upscale_factor)
        ),
        resampling=Resampling.bilinear
    )

    print('Shape before resample:', dataset.shape)
    print('Shape after resample:', data.shape[1:])

    # scale image transform
    dst_transform = dataset.transform * dataset.transform.scale(
        (dataset.width / data.shape[-1]),
        (dataset.height / data.shape[-2])
    )

    print('Transform before resample:\n', dataset.transform, '\n')
    print('Transform after resample:\n', dst_transform)

    ## Write outputs
    # set properties for output
    # dst_kwargs = src.meta.copy()
    # dst_kwargs.update(
    #     {
    #         "crs": dst_crs,
    #         "transform": dst_transform,
    #         "width": data.shape[-1],
    #         "height": data.shape[-2],
    #         "nodata": 0,  
    #     }
    # )

    # with rasterio.open("../temp/LC08_20200518_15m.tif", "w", **dst_kwargs) as dst:
    #     # iterate through bands
    #     for i in range(data.shape[0]):
    #           dst.write(data[i].astype(rasterio.uint32), i+1)
------------------

[0;31m---------------------------------------------------------------------------[0m
[0;31mValueError[0m                                Traceback (most recent call last)
Cell [0;32mIn[1], line 1[0m
[0;32m----> 1[0m [38;5;28;01mimport[39;00m [38;5;21;01mrasterio[39;00m
[1;32m      2[0m [38;5;28;01mfrom[39;00m [38;5;21;01mrasterio[39;00m[38;5;21;01m.[39;00m[38;5;21;01menums[39;00m [38;5;28;01mimport[39;00m Resampling
[1;32m      4[0m image [38;5;241m=[39m [38;5;124m"[39m[38;5;124m../data/LC08_L1TP_224078_20200518_20200518_01_RT.TIF[39m[38;5;124m"[39m

File [0;32m~/miniconda3/envs/pygis2/lib/python3.10/site-packages/rasterio/__init__.py:55[0m
[1;32m     49[0m [38;5;28;01mfrom[39;00m [38;5;21;01mrasterio[39;00m[38;5;21;01m.[39;00m[38;5;21;01menv[39;00m [38;5;28;01mimport[39;00m ensure_env_with_credentials, Env
[1;32m     50[0m [38;5;28;01mfrom[39;00m [38;5;21;01mrasterio[39;00m[38;5;21;01m.[39;00m[38;5;21;01merrors[39;00m [38;5;28;01mimport[39;00m (
[1;32m     51[0m     RasterioIOError,
[1;32m     52[0m     DriverCapabilityError,
[1;32m     53[0m     RasterioDeprecationWarning,
[1;32m     54[0m )
[0;32m---> 55[0m [38;5;28;01mfrom[39;00m [38;5;21;01mrasterio[39;00m[38;5;21;01m.[39;00m[38;5;21;01mio[39;00m [38;5;28;01mimport[39;00m (
[1;32m     56[0m     DatasetReader,
[1;32m     57[0m     get_writer_for_path,
[1;32m     58[0m     get_writer_for_driver,
[1;32m     59[0m     MemoryFile,
[1;32m     60[0m )
[1;32m     61[0m [38;5;28;01mfrom[39;00m [38;5;21;01mrasterio[39;00m[38;5;21;01m.[39;00m[38;5;21;01mprofiles[39;00m [38;5;28;01mimport[39;00m default_gtiff_profile
[1;32m     62[0m [38;5;28;01mfrom[39;00m [38;5;21;01mrasterio[39;00m[38;5;21;01m.[39;00m[38;5;21;01mtransform[39;00m [38;5;28;01mimport[39;00m Affine, guard_transform

File [0;32m~/miniconda3/envs/pygis2/lib/python3.10/site-packages/rasterio/io.py:9[0m
[1;32m      6[0m [38;5;28;01mimport[39;00m [38;5;21;01mlogging[39;00m
[1;32m      8[0m [38;5;28;01mfrom[39;00m [38;5;21;01mrasterio[39;00m[38;5;21;01m.[39;00m[38;5;21;01m_base[39;00m [38;5;28;01mimport[39;00m get_dataset_driver, driver_can_create, driver_can_create_copy
[0;32m----> 9[0m [38;5;28;01mfrom[39;00m [38;5;21;01mrasterio[39;00m[38;5;21;01m.[39;00m[38;5;21;01m_io[39;00m [38;5;28;01mimport[39;00m (
[1;32m     10[0m     DatasetReaderBase,
[1;32m     11[0m     DatasetWriterBase,
[1;32m     12[0m     BufferedDatasetWriterBase,
[1;32m     13[0m     MemoryFileBase,
[1;32m     14[0m )
[1;32m     15[0m [38;5;28;01mfrom[39;00m [38;5;21;01mrasterio[39;00m[38;5;21;01m.[39;00m[38;5;21;01mwindows[39;00m [38;5;28;01mimport[39;00m WindowMethodsMixin
[1;32m     16[0m [38;5;28;01mfrom[39;00m [38;5;21;01mrasterio[39;00m[38;5;21;01m.[39;00m[38;5;21;01menv[39;00m [38;5;28;01mimport[39;00m ensure_env

File [0;32mrasterio/_io.pyx:1[0m, in [0;36minit rasterio._io[0;34m()[0m

[0;31mValueError[0m: numpy.dtype size changed, may indicate binary incompatibility. Expected 96 from C header, got 88 from PyObject
ValueError: numpy.dtype size changed, may indicate binary incompatibility. Expected 96 from C header, got 88 from PyObject

